Workbook
Name CensoCaminho: Filtro_Municipio!$B$5
Name Município: Filtro_Municipio!$B$3
Name SegmentaçãodeDados_DEPENDENCIA: #N/A
Name SegmentaçãodeDados_LOCALIZACAO: #N/A
Name UF: Filtro_Municipio!$B$2

Sheet Dashboard
A1: ="Painel do Censo Escolar 2024 — "&Filtro_Municipio!B3&" ("&Filtro_Municipio!B2&")" -> Painel do Censo Escolar 2024 — Rio Claro (SP)
A2: Totais do recorte carregado. Após trocar UF/Município, use Dados > Atualizar Tudo para atualizar a base.
A4: Escolas no recorte | C4: Escolas ativas | E4: Matrículas básicas | G4: Escolas públicas
A5: =COUNT(DadosTratados!$H:$H) -> 143 | C5: =COUNTIF(DadosTratados!$BK:$BK,"Ativa") -> 122 | E5: =SUM(DadosTratados!$AM:$AM) -> 43081 | G5: =COUNTIF(DadosTratados!$I:$I,1)+COUNTIF(DadosTratados!$I:$I,2)+COUNTIF(DadosTratados!$I:$I,3) -> 101

Sheet Tabelas_Dinâmicas
A1: TABELA DINÂMICA - DEPENDÊNCIA | F1: TABELA DINÂMICA - PORTE
A2: Rótulos de Linha | B2: Contagem de CO_ENTIDADE | F2: Rótulos de Linha | G2: Contagem de CO_ENTIDADE
A3: Estadual | B3: 34 | F3: Grande | G3: 23
A4: Municipal | B4: 67 | F4: Média | G4: 38
A5: Privada | B5: 42 | F5: Microescola | G5: 14
A6: Total Geral | B6: 143 | F6: Muito Grande | G6: 7
F7: Não informado | G7: 21
F8: Pequena | G8: 40
F9: Total Geral | G9: 143
A15: TABELA DINÂMICA - ESGOTO | F15: TABELA DINÂMICA - LIXO
A16: Rótulos de Linha | B16: Contagem de CO_ENTIDADE | F16: Rótulos de Linha | G16: Contagem de CO_ENTIDADE
A17: Fossa séptica | B17: 2 | F17: Descarte em outra área | G17: 1
A18: Não informado | B18: 21 | F18: Não informado | G18: 21
A19: Rede pública | B19: 120 | F19: Serviço de coleta | G19: 121
A20: Total Geral | B20: 143 | F20: Total Geral | G20: 143
A28: TABELA DINÂMICA - RAÇA/COR | F28: TABELA DINÂMICA - ETAPA DE ENSINO
A29: Valores | F29: Valores
A30: Não declarada | B30: 4027 | F30: Educação Infântil | G30: 9411
A31: Branca | B31: 28582 | F31: Fundamental | G31: 22664
A32: Preta | B32: 1287 | F32: Ensino Médio | G32: 8998
A33: Parda | B33: 9060 | F33: Profissional | G33: 2161
A34: Amarela | B34: 99 | F34: Eja | G34: 712
A35: Indígena | B35: 26 | F35: Eduação Especial | G35: 1483
A43: TABELA DINÂMICA - ÁGUA | F43: TABELA DINÂMICA - ENERGIA
A44: Rótulos de Linha | B44: Contagem de CO_ENTIDADE | F44: Rótulos de Linha | G44: Contagem de CO_ENTIDADE
A45: Não informado | B45: 21 | F45: Não informado | G45: 21
A46: Rede pública | B46: 122 | F46: Rede pública | G46: 122
A47: Total Geral | B47: 143 | F47: Total Geral | G47: 143
A55: TABELA DINÂMICA - SEXO
A56: Valores
A57: Feminino | B57: 21172
A58: Masculino | B58: 21909

Sheet Filtro_Municipio
A1: Filtro para consultas Power Query
A2: UF | B2: SP
A3: Município | B3: Rio Claro
A5: Caminho do arquivo Censo: | B5: C:\Users\Rafael\Downloads\Censo_2024_Excel (1) (1)\Censo_2024_Excel.xlsx
A7: Tabela que será lida pelo Power Query
A8: SG_UF | B8: NO_MUNICIPIO
A9: =B2 -> SP | B9: =$B$3 -> Rio Claro

Sheet DadosTratados
A1: NO_REGIAO | B1: NO_UF | C1: SG_UF | D1: CO_UF | E1: NO_MUNICIPIO | F1: CO_MUNICIPIO | G1: NO_ENTIDADE | H1: CO_ENTIDADE | I1: TP_DEPENDENCIA | J1: TP_LOCALIZACAO | K1: TP_LOCALIZACAO_DIFERENCIADA | L1: DS_ENDERECO | M1: NU_ENDERECO | N1: DS_COMPLEMENTO | O1: NO_BAIRRO | P1: CO_CEP | Q1: TP_SITUACAO_FUNCIONAMENTO | R1: IN_AGUA_POTAVEL | S1: IN_AGUA_REDE_PUBLICA | T1: IN_AGUA_POCO_ARTESIANO | U1: IN_AGUA_CACIMBA | V1: IN_AGUA_FONTE_RIO | W1: IN_AGUA_INEXISTENTE | X1: IN_AGUA_CARRO_PIPA | Y1: IN_ENERGIA_REDE_PUBLICA | Z1: IN_ENERGIA_GERADOR_FOSSIL | AA1: IN_ENERGIA_RENOVAVEL | AB1: IN_ENERGIA_INEXISTENTE | AC1: IN_ESGOTO_REDE_PUBLICA | AD1: IN_ESGOTO_FOSSA_SEPTICA | AE1: IN_ESGOTO_FOSSA_COMUM | AF1: IN_ESGOTO_FOSSA | AG1: IN_ESGOTO_INEXISTENTE | AH1: IN_LIXO_SERVICO_COLETA | AI1: IN_LIXO_QUEIMA | AJ1: IN_LIXO_ENTERRA | AK1: IN_LIXO_DESTINO_FINAL_PUBLICO | AL1: IN_LIXO_DESCARTA_OUTRA_AREA | AM1: QT_MAT_BAS | AN1: QT_MAT_INF | AO1: QT_MAT_FUND | AP1: QT_MAT_MED | AQ1: QT_MAT_PROF | AR1: QT_MAT_EJA | AS1: QT_MAT_ESP | AT1: QT_MAT_BAS_FEM | AU1: QT_MAT_BAS_MASC | AV1: QT_MAT_BAS_ND | AW1: QT_MAT_BAS_BRANCA | AX1: QT_MAT_BAS_PRETA | AY1: QT_MAT_BAS_PARDA | AZ1: QT_MAT_BAS_AMARELA | BA1: QT_MAT_BAS_INDIGENA | BB1: QT_MAT_BAS_0_3 | BC1: QT_MAT_BAS_4_5 | BD1: QT_MAT_BAS_6_10 | BE1: QT_MAT_BAS_11_14 | BF1: QT_MAT_BAS_15_17 | BG1: QT_MAT_BAS_18_MAIS | BH1: DEPENDENCIA | BI1: LOCALIZACAO | BJ1: LOC_DIFERENCIADA | BK1: SITUACAO | BL1: TAMANHO_ESCOLA | BM1: AGUA | BN1: ENERGIA | BO1: ESGOTO | BP1: LIXO
A2: Sudeste | B2: São Paulo | C2: SP | D2: 35 | E2: Rio Claro | F2: 3543907 | G2: COLEGIO DOM BOSCO RIO CLARO | H2: 35004193 | I2: 4 | J2: 1 | K2: 0 | L2: 9 | M2: 1742 | O2: CENTRO | P2: 13500220 | Q2: 1 | R2: 1 | S2: 1 | T2: 0 | U2: 0 | V2: 0 | W2: 0 | X2: 0 | Y2: 1 | Z2: 0 | AA2: 0 | AB2: 0 | AC2: 1 | AD2: 0 | AE2: 0 | AF2: 0 | AG2: 0 | AH2: 1 | AI2: 0 | AJ2: 0 | AK2: 0 | AL2: 0 | AM2: 750 | AN2: 106 | AO2: 527 | AP2: 117 | AQ2: 0 | AR2: 0 | AS2: 17 | AT2: 382 | AU2: 368 | AV2: 42 | AW2: 678 | AX2: 8 | AY2: 22 | AZ2: 0 | BA2: 0 | BB2: 38 | BC2: 59 | BD2: 260 | BE2: 268 | BF2: 123 | BG2: 2 | BH2: Privada | BI2: Urbana | BJ2: Não | BK2: Ativa | BL2: Grande | BM2: Rede pública | BN2: Rede pública | BO2: Rede pública | BP2: Serviço de coleta
A3: Sudeste | B3: São Paulo | C3: SP | D3: 35 | E3: Rio Claro | F3: 3543907 | G3: ESCOLA DA BISA EDUCACAO INFANTIL E FUNDAMENTAL | H3: 35004940 | I3: 4 | J3: 1 | K3: 0 | L3: 12 | M3: 1931 | O3: CENTRO | P3: 13500250 | Q3: 1 | R3: 1 | S3: 1 | T3: 0 | U3: 0 | V3: 0 | W3: 0 | X3: 0 | Y3: 1 | Z3: 0 | AA3: 0 | AB3: 0 | AC3: 1 | AD3: 0 | AE3: 0 | AF3: 0 | AG3: 0 | AH3: 1 | AI3: 0 | AJ3: 0 | AK3: 0 | AL3: 0 | AM3: 186 | AN3: 54 | AO3: 132 | AP3: 0 | AQ3: 0 | AR3: 0 | AS3: 3 | AT3: 80 | AU3: 106 | AV3: 30 | AW3: 141 | AX3: 1 | AY3: 12 | AZ3: 2 | BA3: 0 | BB3: 0 | BC3: 52 | BD3: 133 | BE3: 1 | BF3: 0 | BG3: 0 | BH3: Privada | BI3: Urbana | BJ3: Não | BK3: Ativa | BL3: Pequena | BM3: Rede pública | BN3: Rede pública | BO3: Rede pública | BP3: Serviço de coleta
A4: Sudeste | B4: São Paulo | C4: SP | D4: 35 | E4: Rio Claro | F4: 3543907 | G4: CENTRO DE CONVIVENCIA INFANTIL UNESPINHA | H4: 35005166 | I4: 2 | J4: 1 | K4: 0 | L4: 16 B | M4: 1347 | O4: VILA BELA VISTA | P4: 13506752 | Q4: 1 | R4: 1 | S4: 1 | T4: 0 | U4: 0 | V4: 0 | W4: 0 | X4: 0 | Y4: 1 | Z4: 0 | AA4: 0 | AB4: 0 | AC4: 0 | AD4: 1 | AE4: 0 | AF4: 1 | AG4: 0 | AH4: 1 | AI4: 0 | AJ4: 0 | AK4: 0 | AL4: 0 | AM4: 18 | AN4: 18 | AO4: 0 | AP4: 0 | AQ4: 0 | AR4: 0 | AS4: 0 | AT4: 7 | AU4: 11 | AV4: 0 | AW4: 18 | AX4: 0 | AY4: 0 | AZ4: 0 | BA4: 0 | BB4: 18 | BC4: 0 | BD4: 0 | BE4: 0 | BF4: 0 | BG4: 0 | BH4: Estadual | BI4: Urbana | BJ4: Não | BK4: Ativa | BL4: Microescola | BM4: Rede pública | BN4: Rede pública | BO4: Fossa séptica | BP4: Serviço de coleta
A5: Sudeste | B5: São Paulo | C5: SP | D5: 35 | E5: Rio Claro | F5: 3543907 | G5: ESCOLA MUNICIPAL PROFESSORA MARILDA DOS SANTOS SOUZA | H5: 35005006 | I5: 3 | J5: 1 | K5: 0 | L5: AVENIDA 01 SM | M5: 41 | O5: JARDIM RESIDENCIAL SAN MARINO | P5: 13503719 | Q5: 1 | R5: 1 | S5: 1 | T5: 0 | U5: 0 | V5: 0 | W5: 0 | X5: 0 | Y5: 1 | Z5: 0 | AA5: 0 | AB5: 0 | AC5: 1 | AD5: 0 | AE5: 0 | AF5: 0 | AG5: 0 | AH5: 1 | AI5: 0 | AJ5: 0 | AK5: 0 | AL5: 0 | AM5: 151 | AN5: 151 | AO5: 0 | AP5: 0 | AQ5: 0 | AR5: 0 | AS5: 6 | AT5: 82 | AU5: 69 | AV5: 4 | AW5: 106 | AX5: 10 | AY5: 31 | AZ5: 0 | BA5: 0 | BB5: 103 | BC5: 44 | BD5: 4 | BE5: 0 | BF5: 0 | BG5: 0 | BH5: Municipal | BI5: Urbana | BJ5: Não | BK5: Ativa | BL5: Pequena | BM5: Rede pública | BN5: Rede pública | BO5: Rede pública | BP5: Serviço de coleta
A6: Sudeste | B6: São Paulo | C6: SP | D6: 35 | E6: Rio Claro | F6: 3543907 | G6: ESCOLA MUNICIPAL PROFESSORA RUTINEIA PAULINO DE SOUZA FERREIRA DA SILVA | H6: 35005440 | I6: 3 | J6: 1 | K6: 0 | L6: 1 JN | M6: 1056 | O6: JARDIM NOVO 1 | P6: 13502740 | Q6: 1 | R6: 1 | S6: 1 | T6: 0 | U6: 0 | V6: 0 | W6: 0 | X6: 0 | Y6: 1 | Z6: 0 | AA6: 0 | AB6: 0 | AC6: 1 | AD6: 0 | AE6: 0 | AF6: 0 | AG6: 0 | AH6: 1 | AI6: 0 | AJ6: 0 | AK6: 0 | AL6: 0 | AM6: 124 | AN6: 124 | AO6: 0 | AP6: 0 | AQ6: 0 | AR6: 0 | AS6: 3 | AT6: 57 | AU6: 67 | AV6: 6 | AW6: 64 | AX6: 8 | AY6: 46 | AZ6: 0 | BA6: 0 | BB6: 118 | BC6: 6 | BD6: 0 | BE6: 0 | BF6: 0 | BG6: 0 | BH6: Municipal | BI6: Urbana | BJ6: Não | BK6: Ativa | BL6: Pequena | BM6: Rede pública | BN6: Rede pública | BO6: Rede pública | BP6: Serviço de coleta
A7: Sudeste | B7: São Paulo | C7: SP | D7: 35 | E7: Rio Claro | F7: 3543907 | G7: ESCOLA MUNICIPAL PROFESSOR OCTAVIO JOSE CHIOSSI | H7: 35005971 | I7: 3 | J7: 1 | K7: 0 | L7: 5 JN | M7: 1129 | O7: JARDIM NOVO | P7: 13502760 | Q7: 1 | R7: 1 | S7: 1 | T7: 0 | U7: 0 | V7: 0 | W7: 0 | X7: 0 | Y7: 1 | Z7: 0 | AA7: 0 | AB7: 0 | AC7: 1 | AD7: 0 | AE7: 0 | AF7: 0 | AG7: 0 | AH7: 1 | AI7: 0 | AJ7: 0 | AK7: 0 | AL7: 0 | AM7: 411 | AN7: 0 | AO7: 396 | AP7: 0 | AQ7: 0 | AR7: 15 | AS7: 13 | AT7: 204 | AU7: 207 | AV7: 43 | AW7: 214 | AX7: 9 | AY7: 145 | AZ7: 0 | BA7: 0 | BB7: 0 | BC7: 0 | BD7: 379 | BE7: 17 | BF7: 0 | BG7: 15 | BH7: Municipal | BI7: Urbana | BJ7: Não | BK7: Ativa | BL7: Média | BM7: Rede pública | BN7: Rede pública | BO7: Rede pública | BP7: Serviço de coleta
A8: Sudeste | B8: São Paulo | C8: SP | D8: 35 | E8: Rio Claro | F8: 3543907 | G8: ESCOLA MUNICIPAL PROFESSORA GISELE BRIZOTTI FERRAZ FERREIRA | H8: 35006329 | I8: 3 | J8: 1 | K8: 0 | L8: AVENIDA BRASIL | M8: 1233 | O8: JARDIM FLORIDIANA | P8: 13505018 | Q8: 1 | R8: 1 | S8: 1 | T8: 0 | U8: 0 | V8: 0 | W8: 0 | X8: 0 | Y8: 1 | Z8: 0 | AA8: 0 | AB8: 0 | AC8: 1 | AD8: 0 | AE8: 0 | AF8: 0 | AG8: 0 | AH8: 1 | AI8: 0 | AJ8: 0 | AK8: 0 | AL8: 0 | AM8: 73 | AN8: 73 | AO8: 0 | AP8: 0 | AQ8: 0 | AR8: 0 | AS8: 2 | AT8: 34 | AU8: 39 | AV8: 27 | AW8: 38 | AX8: 3 | AY8: 5 | AZ8: 0 | BA8: 0 | BB8: 73 | BC8: 0 | BD8: 0 | BE8: 0 | BF8: 0 | BG8: 0 | BH8: Municipal | BI8: Urbana | BJ8: Não | BK8: Ativa | BL8: Pequena | BM8: Rede pública | BN8: Rede pública | BO8: Rede pública | BP8: Serviço de coleta
A9: Sudeste | B9: São Paulo | C9: SP | D9: 35 | E9: Rio Claro | F9: 3543907 | G9: COLEGIO DAGAMA | H9: 35007056 | I9: 4 | J9: 1 | K9: 0 | L9: 22 BE | M9: 669 | O9: ESTADIO | P9: 13501388 | Q9: 1 | R9: 1 | S9: 1 | T9: 0 | U9: 0 | V9: 0 | W9: 0 | X9: 0 | Y9: 1 | Z9: 0 | AA9: 0 | AB9: 0 | AC9: 1 | AD9: 0 | AE9: 0 | AF9: 0 | AG9: 0 | AH9: 1 | AI9: 0 | AJ9: 0 | AK9: 0 | AL9: 0 | AM9: 321 | AN9: 55 | AO9: 266 | AP9: 0 | AQ9: 0 | AR9: 0 | AS9: 5 | AT9: 146 | AU9: 175 | AV9: 14 | AW9: 281 | AX9: 8 | AY9: 18 | AZ9: 0 | BA9: 0 | BB9: 8 | BC9: 37 | BD9: 162 | BE9: 111 | BF9: 3 | BG9: 0 | BH9: Privada | BI9: Urbana | BJ9: Não | BK9: Ativa | BL9: Média | BM9: Rede pública | BN9: Rede pública | BO9: Rede pública | BP9: Serviço de coleta
A10: Sudeste | B10: São Paulo | C10: SP | D10: 35 | E10: Rio Claro | F10: 3543907 | G10: ESCOLA MUNICIPAL DR DJALMA OUTEIRO PINTO | H10: 35007338 | I10: 3 | J10: 1 | K10: 0 | L10: 8 | M10: 3609 | O10: ALTO DO SANTANA | P10: 13504188 | Q10: 1 | R10: 1 | S10: 1 | T10: 0 | U10: 0 | V10: 0 | W10: 0 | X10: 0 | Y10: 1 | Z10: 0 | AA10: 0 | AB10: 0 | AC10: 1 | AD10: 0 | AE10: 0 | AF10: 0 | AG10: 0 | AH10: 1 | AI10: 0 | AJ10: 0 | AK10: 0 | AL10: 0 | AM10: 44 | AN10: 44 | AO10: 0 | AP10: 0 | AQ10: 0 | AR10: 0 | AS10: 0 | AT10: 27 | AU10: 17 | AV10: 6 | AW10: 32 | AX10: 1 | AY10: 5 | AZ10: 0 | BA10: 0 | BB10: 44 | BC10: 0 | BD10: 0 | BE10: 0 | BF10: 0 | BG10: 0 | BH10: Municipal | BI10: Urbana | BJ10: Não | BK10: Ativa | BL10: Microescola | BM10: Rede pública | BN10: Rede pública | BO10: Rede pública | BP10: Serviço de coleta
A11: Sudeste | B11: São Paulo | C11: SP | D11: 35 | E11: Rio Claro | F11: 3543907 | G11: ESCOLA MUNICIPAL PROFESSORA LUCIA HELENA FERREIRA CAMARGO | H11: 35007339 | I11: 3 | J11: 1 | K11: 0 | L11: 5 | M11: 360 | O11: JARDIM ARAUCARIA | P11: 13504824 | Q11: 1 | R11: 1 | S11: 1 | T11: 0 | U11: 0 | V11: 0 | W11: 0 | X11: 0 | Y11: 1 | Z11: 0 | AA11: 0 | AB11: 0 | AC11: 1 | AD11: 0 | AE11: 0 | AF11: 0 | AG11: 0 | AH11: 1 | AI11: 0 | AJ11: 0 | AK11: 0 | AL11: 0 | AM11: 116 | AN11: 116 | AO11: 0 | AP11: 0 | AQ11: 0 | AR11: 0 | AS11: 2 | AT11: 70 | AU11: 46 | AV11: 3 | AW11: 69 | AX11: 4 | AY11: 40 | AZ11: 0 | BA11: 0 | BB11: 113 | BC11: 3 | BD11: 0 | BE11: 0 | BF11: 0 | BG11: 0 | BH11: Municipal | BI11: Urbana | BJ11: Não | BK11: Ativa | BL11: Pequena | BM11: Rede pública | BN11: Rede pública | BO11: Rede pública | BP11: Serviço de coleta
A12: Sudeste | B12: São Paulo | C12: SP | D12: 35 | E12: Rio Claro | F12: 3543907 | G12: ESCOLA MUNICIPAL THEODORO PAULO KOELLE | H12: 35007528 | I12: 3 | J12: 1 | K12: 0 | L12: 17 JN | M12: 1433 | O12: JARDIM NOVO II | P12: 13502714 | Q12: 1 | R12: 1 | S12: 1 | T12: 0 | U12: 0 | V12: 0 | W12: 0 | X12: 0 | Y12: 1 | Z12: 0 | AA12: 0 | AB12: 0 | AC12: 1 | AD12: 0 | AE12: 0 | AF12: 0 | AG12: 0 | AH12: 1 | AI12: 0 | AJ12: 0 | AK12: 0 | AL12: 0 | AM12: 217 | AN12: 0 | AO12: 217 | AP12: 0 | AQ12: 0 | AR12: 0 | AS12: 10 | AT12: 109 | AU12: 108 | AV12: 21 | AW12: 117 | AX12: 3 | AY12: 75 | AZ12: 0 | BA12: 1 | BB12: 0 | BC12: 0 | BD12: 208 | BE12: 9 | BF12: 0 | BG12: 0 | BH12: Municipal | BI12: Urbana | BJ12: Não | BK12: Ativa | BL12: Média | BM12: Rede pública | BN12: Rede pública | BO12: Rede pública | BP12: Serviço de coleta
A13: Sudeste | B13: São Paulo | C13: SP | D13: 35 | E13: Rio Claro | F13: 3543907 | G13: ESCOLA MUNICIPAL PROFESSOR GUNAR WILHELM KOELLE | H13: 35007533 | I13: 3 | J13: 1 | K13: 0 | L13: 18 JN | M13: 409 | O13: JARDIM NOVO | P13: 13502762 | Q13: 1 | R13: 1 | S13: 1 | T13: 0 | U13: 0 | V13: 0 | W13: 0 | X13: 0 | Y13: 1 | Z13: 0 | AA13: 0 | AB13: 0 | AC13: 1 | AD13: 0 | AE13: 0 | AF13: 0 | AG13: 0 | AH13: 1 | AI13: 0 | AJ13: 0 | AK13: 0 | AL13: 0 | AM13: 305 | AN13: 305 | AO13: 0 | AP13: 0 | AQ13: 0 | AR13: 0 | AS13: 7 | AT13: 152 | AU13: 153 | AV13: 20 | AW13: 171 | AX13: 24 | AY13: 90 | AZ13: 0 | BA13: 0 | BB13: 131 | BC13: 155 | BD13: 19 | BE13: 0 | BF13: 0 | BG13: 0 | BH13: Municipal | BI13: Urbana | BJ13: Não | BK13: Ativa | BL13: Média | BM13: Rede pública | BN13: Rede pública | BO13: Rede pública | BP13: Serviço de coleta
... A18: Sudeste | B18: São Paulo | C18: SP | D18: 35 | E18: Rio Claro | F18: 3543907 | G18: TRIGONO EDUCACAO INFANTIL | H18: 35009311 | I18: 4 | J18: 1 | K18: 0 | L18: 40 | M18: 522 | O18: VILA OPERARIA | P18: 13504140 | Q18: 1 | R18: 1 | S18: 1 | T18: 0 | U18: 0 | V18: 0 | W18: 0 | X18: 0 | Y18: 1 | Z18: 0 | AA18: 0 | AB18: 0 | AC18: 1 | AD18: 0 | AE18: 0 | AF18: 0 | AG18: 0 | AH18: 1 | AI18: 0 | AJ18: 0 | AK18: 0 | AL18: 0 | AM18: 65 | AN18: 65 | AO18: 0 | AP18: 0 | AQ18: 0 | AR18: 0 | AS18: 0 | AT18: 34 | AU18: 31 | AV18: 22 | AW18: 42 | AX18: 0 | AY18: 1 | AZ18: 0 | BA18: 0 | BB18: 33 | BC18: 31 | BD18: 1 | BE18: 0 | BF18: 0 | BG18: 0 | BH18: Privada | BI18: Urbana | BJ18: Não | BK18: Ativa | BL18: Pequena | BM18: Rede pública | BN18: Rede pública | BO18: Rede pública | BP18: Serviço de coleta
A19: Sudeste | B19: São Paulo | C19: SP | D19: 35 | E19: Rio Claro | F19: 3543907 | G19: COLEGIO TRIGONO COMPLEXO EDUCACIONAL | H19: 35009638 | I19: 4 | J19: 1 | K19: 0 | L19: 5 A | M19: 236 | N19: AVENIDA 5A | O19: CIDADE NOVA | P19: 13506795 | Q19: 1 | R19: 1 | S19: 1 | T19: 0 | U19: 0 | V19: 0 | W19: 0 | X19: 0 | Y19: 1 | Z19: 0 | AA19: 0 | AB19: 0 | AC19: 1 | AD19: 0 | AE19: 0 | AF19: 0 | AG19: 0 | AH19: 1 | AI19: 0 | AJ19: 0 | AK19: 0 | AL19: 0 | AM19: 40 | AN19: 0 | AO19: 40 | AP19: 0 | AQ19: 0 | AR19: 0 | AS19: 1 | AT19: 17 | AU19: 23 | AV19: 2 | AW19: 35 | AX19: 0 | AY19: 3 | AZ19: 0 | BA19: 0 | BB19: 0 | BC19: 0 | BD19: 40 | BE19: 0 | BF19: 0 | BG19: 0 | BH19: Privada | BI19: Urbana | BJ19: Não | BK19: Ativa | BL19: Microescola | BM19: Rede pública | BN19: Rede pública | BO19: Rede pública | BP19: Serviço de coleta
A20: Sudeste | B20: São Paulo | C20: SP | D20: 35 | E20: Rio Claro | F20: 3543907 | G20: ESCOLA MUNICIPAL PROFESSOR ALDO ZOTTARELLI JUNIOR | H20: 35009802 | I20: 3 | J20: 1 | K20: 0 | L20: 10 JC | M20: 589 | O20: BENJAMIN DE CASTRO | P20: 13503504 | Q20: 1 | R20: 1 | S20: 1 | T20: 0 | U20: 0 | V20: 0 | W20: 0 | X20: 0 | Y20: 1 | Z20: 0 | AA20: 0 | AB20: 0 | AC20: 1 | AD20: 0 | AE20: 0 | AF20: 0 | AG20: 0 | AH20: 1 | AI20: 0 | AJ20: 0 | AK20: 0 | AL20: 0 | AM20: 357 | AN20: 0 | AO20: 357 | AP20: 0 | AQ20: 0 | AR20: 0 | AS20: 13 | AT20: 165 | AU20: 192 | AV20: 23 | AW20: 197 | AX20: 20 | AY20: 117 | AZ20: 0 | BA20: 0 | BB20: 0 | BC20: 0 | BD20: 336 | BE20: 20 | BF20: 1 | BG20: 0 | BH20: Municipal | BI20: Urbana | BJ20: Não | BK20: Ativa | BL20: Média | BM20: Rede pública | BN20: Rede pública | BO20: Rede pública | BP20: Serviço de coleta
A21: Sudeste | B21: São Paulo | C21: SP | D21: 35 | E21: Rio Claro | F21: 3543907 | G21: ESCOLA MUNICIPAL PROFESSORA EDNA CRISTINA FARDIM FERNANDES | H21: 35009863 | I21: 3 | J21: 1 | K21: 0 | L21: P 27 | M21: 123 | O21: VILA PAULISTA | P21: 13506832 | Q21: 1 | R21: 1 | S21: 1 | T21: 0 | U21: 0 | V21: 0 | W21: 0 | X21: 0 | Y21: 1 | Z21: 0 | AA21: 0 | AB21: 0 | AC21: 1 | AD21: 0 | AE21: 0 | AF21: 0 | AG21: 0 | AH21: 1 | AI21: 0 | AJ21: 0 | AK21: 0 | AL21: 0 | AM21: 74 | AN21: 74 | AO21: 0 | AP21: 0 | AQ21: 0 | AR21: 0 | AS21: 1 | AT21: 45 | AU21: 29 | AV21: 13 | AW21: 45 | AX21: 5 | AY21: 10 | AZ21: 1 | BA21: 0 | BB21: 72 | BC21: 2 | BD21: 0 | BE21: 0 | BF21: 0 | BG21: 0 | BH21: Municipal | BI21: Urbana | BJ21: Não | BK21: Ativa | BL21: Pequena | BM21: Rede pública | BN21: Rede pública | BO21: Rede pública | BP21: Serviço de coleta
A22: Sudeste | B22: São Paulo | C22: SP | D22: 35 | E22: Rio Claro | F22: 3543907 | G22: ESCOLA MUNICIPAL DO RESIDENCIAL DOS BOSQUES | H22: 35010574 | I22: 3 | J22: 1 | K22: 0 | L22: RUA 3 VLA | M22: 529 | O22: VILA ANHANGUERA | P22: 13503532 | Q22: 1 | R22: 0 | S22: 1 | T22: 0 | U22: 0 | V22: 0 | W22: 0 | X22: 0 | Y22: 1 | Z22: 0 | AA22: 0 | AB22: 0 | AC22: 1 | AD22: 0 | AE22: 0 | AF22: 0 | AG22: 0 | AH22: 1 | AI22: 0 | AJ22: 0 | AK22: 0 | AL22: 0 | AM22: 63 | AN22: 63 | AO22: 0 | AP22: 0 | AQ22: 0 | AR22: 0 | AS22: 0 | AT22: 31 | AU22: 32 | AV22: 4 | AW22: 38 | AX22: 7 | AY22: 14 | AZ22: 0 | BA22: 0 | BB22: 62 | BC22: 1 | BD22: 0 | BE22: 0 | BF22: 0 | BG22: 0 | BH22: Municipal | BI22: Urbana | BJ22: Não | BK22: Ativa | BL22: Pequena | BM22: Rede pública | BN22: Rede pública | BO22: Rede pública | BP22: Serviço de coleta
A23: Sudeste | B23: São Paulo | C23: SP | D23: 35 | E23: Rio Claro | F23: 3543907 | G23: SEST SENAT RIO CLARO | H23: 35010818 | I23: 4 | J23: 1 | K23: 0 | L23: RODOVIA WASHINGTON LUIZ | M23: 176 | O23: JARDIM RIO CLARO | P23: 13503750 | Q23: 1 | R23: 1 | S23: 1 | T23: 0 | U23: 0 | V23: 0 | W23: 0 | X23: 0 | Y23: 1 | Z23: 0 | AA23: 0 | AB23: 0 | AC23: 1 | AD23: 0 | AE23: 0 | AF23: 0 | AG23: 0 | AH23: 1 | AI23: 0 | AJ23: 0 | AK23: 0 | AL23: 0 | AM23: 44 | AN23: 0 | AO23: 0 | AP23: 0 | AQ23: 44 | AR23: 0 | AS23: 0 | AT23: 13 | AU23: 31 | AV23: 25 | AW23: 12 | AX23: 1 | AY23: 5 | AZ23: 1 | BA23: 0 | BB23: 0 | BC23: 0 | BD23: 0 | BE23: 0 | BF23: 0 | BG23: 44 | BH23: Privada | BI23: Urbana | BJ23: Não | BK23: Ativa | BL23: Microescola | BM23: Rede pública | BN23: Rede pública | BO23: Rede pública | BP23: Serviço de coleta
A24: Sudeste | B24: São Paulo | C24: SP | D24: 35 | E24: Rio Claro | F24: 3543907 | G24: CAROLINA AUGUSTA SERAPHIM PROFESSORA | H24: 35021556 | I24: 2 | J24: 1 | K24: 0 | L24: CINCO B | M24: 1191 | N24: RUA | O24: VILA INDAIA | P24: 13506734 | Q24: 1 | R24: 1 | S24: 1 | T24: 0 | U24: 0 | V24: 0 | W24: 0 | X24: 0 | Y24: 1 | Z24: 0 | AA24: 0 | AB24: 0 | AC24: 1 | AD24: 0 | AE24: 0 | AF24: 0 | AG24: 0 | AH24: 1 | AI24: 0 | AJ24: 0 | AK24: 0 | AL24: 0 | AM24: 287 | AN24: 0 | AO24: 287 | AP24: 0 | AQ24: 0 | AR24: 0 | AS24: 8 | AT24: 135 | AU24: 152 | AV24: 1 | AW24: 216 | AX24: 17 | AY24: 53 | AZ24: 0 | BA24: 0 | BB24: 0 | BC24: 0 | BD24: 0 | BE24: 276 | BF24: 11 | BG24: 0 | BH24: Estadual | BI24: Urbana | BJ24: Não | BK24: Ativa | BL24: Média | BM24: Rede pública | BN24: Rede pública | BO24: Rede pública | BP24: Serviço de coleta
A25: Sudeste | B25: São Paulo | C25: SP | D25: 35 | E25: Rio Claro | F25: 3543907 | G25: MONSENHOR MARTINS | H25: 35021568 | I25: 2 | J25: 1 | L25: AV 36 | M25: 717 | N25: AVENIDA | O25: VL OPERARIA | P25: 13504120 | Q25: 2 | BH25: Estadual | BI25: Urbana | BK25: Inativa | BL25: Não informado | BM25: Não informado | BN25: Não informado | BO25: Não informado | BP25: Não informado
A26: Sudeste | B26: São Paulo | C26: SP | D26: 35 | E26: Rio Claro | F26: 3543907 | G26: JOAQUIM SALLES CORONEL | H26: 35021573 | I26: 2 | J26: 1 | K26: 0 | L26: SETE | M26: 793 | N26: RUA | O26: CENTRO | P26: 13500143 | Q26: 1 | R26: 1 | S26: 1 | T26: 0 | U26: 0 | V26: 0 | W26: 0 | X26: 0 | Y26: 1 | Z26: 0 | AA26: 0 | AB26: 0 | AC26: 1 | AD26: 0 | AE26: 0 | AF26: 0 | AG26: 0 | AH26: 1 | AI26: 0 | AJ26: 0 | AK26: 0 | AL26: 0 | AM26: 389 | AN26: 0 | AO26: 389 | AP26: 0 | AQ26: 0 | AR26: 0 | AS26: 15 | AT26: 195 | AU26: 194 | AV26: 7 | AW26: 290 | AX26: 19 | AY26: 72 | AZ26: 1 | BA26: 0 | BB26: 0 | BC26: 0 | BD26: 0 | BE26: 372 | BF26: 17 | BG26: 0 | BH26: Estadual | BI26: Urbana | BJ26: Não | BK26: Ativa | BL26: Média | BM26: Rede pública | BN26: Rede pública | BO26: Rede pública | BP26: Serviço de coleta
A27: Sudeste | B27: São Paulo | C27: SP | D27: 35 | E27: Rio Claro | F27: 3543907 | G27: DJILIAH CAMARGO DE SOUZA PROFA | H27: 35021593 | I27: 2 | J27: 1 | L27: R 4A | M27: 1098 | O27: JARDIM IPE | P27: 13506541 | Q27: 2 | BH27: Estadual | BI27: Urbana | BK27: Inativa | BL27: Não informado | BM27: Não informado | BN27: Não informado | BO27: Não informado | BP27: Não informado
A28: Sudeste | B28: São Paulo | C28: SP | D28: 35 | E28: Rio Claro | F28: 3543907 | G28: JOAQUIM RIBEIRO | H28: 35021611 | I28: 2 | J28: 1 | K28: 0 | L28: SEIS | M28: 437 | N28: RUA | O28: CENTRO | P28: 13500050 | Q28: 1 | R28: 1 | S28: 1 | T28: 0 | U28: 0 | V28: 0 | W28: 0 | X28: 0 | Y28: 1 | Z28: 0 | AA28: 0 | AB28: 0 | AC28: 1 | AD28: 0 | AE28: 0 | AF28: 0 | AG28: 0 | AH28: 1 | AI28: 0 | AJ28: 0 | AK28: 0 | AL28: 0 | AM28: 387 | AN28: 0 | AO28: 0 | AP28: 250 | AQ28: 32 | AR28: 137 | AS28: 21 | AT28: 225 | AU28: 162 | AV28: 40 | AW28: 244 | AX28: 10 | AY28: 91 | AZ28: 1 | BA28: 1 | BB28: 0 | BC28: 0 | BD28: 0 | BE28: 0 | BF28: 237 | BG28: 150 | BH28: Estadual | BI28: Urbana | BJ28: Não | BK28: Ativa | BL28: Média | BM28: Rede pública | BN28: Rede pública | BO28: Rede pública | BP28: Serviço de coleta
A29: Sudeste | B29: São Paulo | C29: SP | D29: 35 | E29: Rio Claro | F29: 3543907 | G29: MARCELLO SCHMIDT | H29: 35021660 | I29: 2 | J29: 1 | L29: AV 1 | M29: 356 | O29: CENTRO | P29: 13500401 | Q29: 2 | BH29: Estadual | BI29: Urbana | BK29: Inativa | BL29: Não informado | BM29: Não informado | BN29: Não informado | BO29: Não informado | BP29: Não informado
A30: Sudeste | B30: São Paulo | C30: SP | D30: 35 | E30: Rio Claro | F30: 3543907 | G30: MARCIANO DE TOLEDO PIZA PROFESSOR | H30: 35021696 | I30: 2 | J30: 1 | K30: 0 | L30: NAVARRO DE ANDRADE | M30: 139 | N30: AVENIDA | O30: CIDADE NOVA | P30: 13506820 | Q30: 1 | R30: 1 | S30: 1 | T30: 0 | U30: 0 | V30: 0 | W30: 0 | X30: 0 | Y30: 1 | Z30: 0 | AA30: 0 | AB30: 0 | AC30: 1 | AD30: 0 | AE30: 0 | AF30: 0 | AG30: 0 | AH30: 1 | AI30: 0 | AJ30: 0 | AK30: 0 | AL30: 0 | AM30: 305 | AN30: 0 | AO30: 0 | AP30: 305 | AQ30: 0 | AR30: 0 | AS30: 4 | AT30: 176 | AU30: 129 | AV30: 12 | AW30: 228 | AX30: 15 | AY30: 49 | AZ30: 1 | BA30: 0 | BB30: 0 | BC30: 0 | BD30: 0 | BE30: 1 | BF30: 279 | BG30: 25 | BH30: Estadual | BI30: Urbana | BJ30: Não | BK30: Ativa | BL30: Média | BM30: Rede pública | BN30: Rede pública | BO30: Rede pública | BP30: Serviço de coleta
A31: Sudeste | B31: São Paulo | C31: SP | D31: 35 | E31: Rio Claro | F31: 3543907 | G31: JOAO BATISTA LEME PROFESSOR | H31: 35021702 | I31: 2 | J31: 1 | K31: 0 | L31: BRASIL | M31: 182 | N31: AVENIDA | O31: VILA ALEMA | P31: 13505151 | Q31: 1 | R31: 1 | S31: 1 | T31: 0 | U31: 0 | V31: 0 | W31: 0 | X31: 0 | Y31: 1 | Z31: 0 | AA31: 0 | AB31: 0 | AC31: 1 | AD31: 0 | AE31: 0 | AF31: 0 | AG31: 0 | AH31: 1 | AI31: 0 | AJ31: 0 | AK31: 0 | AL31: 0 | AM31: 757 | AN31: 0 | AO31: 584 | AP31: 173 | AQ31: 52 | AR31: 0 | AS31: 21 | AT31: 342 | AU31: 415 | AV31: 57 | AW31: 530 | AX31: 17 | AY31: 151 | AZ31: 2 | BA31: 0 | BB31: 0 | BC31: 0 | BD31: 0 | BE31: 552 | BF31: 197 | BG31: 8 | BH31: Estadual | BI31: Urbana | BJ31: Não | BK31: Ativa | BL31: Grande | BM31: Rede pública | BN31: Rede pública | BO31: Rede pública | BP31: Serviço de coleta
A32: Sudeste | B32: São Paulo | C32: SP | D32: 35 | E32: Rio Claro | F32: 3543907 | G32: MICHEL ANTONIO ALEM PROFESSOR | H32: 35021726 | I32: 2 | J32: 1 | K32: 0 | L32: TREZE | M32: 1858 | N32: AVENIDA | O32: CONSOLACAO | P32: 13503400 | Q32: 1 | R32: 1 | S32: 1 | T32: 0 | U32: 0 | V32: 0 | W32: 0 | X32: 0 | Y32: 1 | Z32: 0 | AA32: 0 | AB32: 0 | AC32: 1 | AD32: 0 | AE32: 0 | AF32: 0 | AG32: 0 | AH32: 1 | AI32: 0 | AJ32: 0 | AK32: 0 | AL32: 0 | AM32: 926 | AN32: 0 | AO32: 480 | AP32: 446 | AQ32: 20 | AR32: 0 | AS32: 21 | AT32: 442 | AU32: 484 | AV32: 89 | AW32: 604 | AX32: 20 | AY32: 210 | AZ32: 1 | BA32: 2 | BB32: 0 | BC32: 0 | BD32: 4 | BE32: 433 | BF32: 436 | BG32: 53 | BH32: Estadual | BI32: Urbana | BJ32: Não | BK32: Ativa | BL32: Grande | BM32: Rede pública | BN32: Rede pública | BO32: Rede pública | BP32: Serviço de coleta
A33: Sudeste | B33: São Paulo | C33: SP | D33: 35 | E33: Rio Claro | F33: 3543907 | G33: ODILON CORREA PROFESSOR | H33: 35021738 | I33: 2 | J33: 1 | K33: 0 | L33: 17 | M33: 1726 | N33: RUA | O33: CIDADE CLARET | P33: 13503185 | Q33: 1 | R33: 1 | S33: 1 | T33: 0 | U33: 0 | V33: 0 | W33: 0 | X33: 0 | Y33: 1 | Z33: 0 | AA33: 0 | AB33: 0 | AC33: 1 | AD33: 0 | AE33: 0 | AF33: 0 | AG33: 0 | AH33: 1 | AI33: 0 | AJ33: 0 | AK33: 0 | AL33: 0 | AM33: 1143 | AN33: 0 | AO33: 534 | AP33: 609 | AQ33: 0 | AR33: 0 | AS33: 32 | AT33: 552 | AU33: 591 | AV33: 16 | AW33: 727 | AX33: 31 | AY33: 369 | AZ33: 0 | BA33: 0 | BB33: 0 | BC33: 0 | BD33: 0 | BE33: 489 | BF33: 591 | BG33: 63 | BH33: Estadual | BI33: Urbana | BJ33: Não | BK33: Ativa | BL33: Muito Grande | BM33: Rede pública | BN33: Rede pública | BO33: Rede pública | BP33: Serviço de coleta
A34: Sudeste | B34: São Paulo | C34: SP | D34: 35 | E34: Rio Claro | F34: 3543907 | G34: RAUL FERNANDES CHANCELER | H34: 35021748 | I34: 2 | J34: 1 | K34: 0 | L34: DOIS | M34: 2877 | N34: RUA | O34: VILA OPERARIA | P34: 13504090 | Q34: 1 | R34: 1 | S34: 1 | T34: 0 | U34: 0 | V34: 0 | W34: 0 | X34: 0 | Y34: 1 | Z34: 0 | AA34: 0 | AB34: 0 | AC34: 1 | AD34: 0 | AE34: 0 | AF34: 0 | AG34: 0 | AH34: 1 | AI34: 0 | AJ34: 0 | AK34: 0 | AL34: 0 | AM34: 299 | AN34: 0 | AO34: 0 | AP34: 299 | AQ34: 71 | AR34: 0 | AS34: 16 | AT34: 171 | AU34: 128 | AV34: 6 | AW34: 237 | AX34: 10 | AY34: 45 | AZ34: 1 | BA34: 0 | BB34: 0 | BC34: 0 | BD34: 0 | BE34: 0 | BF34: 280 | BG34: 19 | BH34: Estadual | BI34: Urbana | BJ34: Não | BK34: Ativa | BL34: Média | BM34: Rede pública | BN34: Rede pública | BO34: Rede pública | BP34: Serviço de coleta
A35: Sudeste | B35: São Paulo | C35: SP | D35: 35 | E35: Rio Claro | F35: 3543907 | G35: BARAO DE PIRACICABA | H35: 35021787 | I35: 2 | J35: 1 | K35: 0 | L35: OITO | M35: 2699 | N35: RUA | O35: SANTANA | P35: 13504096 | Q35: 1 | R35: 1 | S35: 1 | T35: 0 | U35: 0 | V35: 0 | W35: 0 | X35: 0 | Y35: 1 | Z35: 0 | AA35: 0 | AB35: 0 | AC35: 1 | AD35: 0 | AE35: 0 | AF35: 0 | AG35: 0 | AH35: 1 | AI35: 0 | AJ35: 0 | AK35: 0 | AL35: 0 | AM35: 661 | AN35: 0 | AO35: 661 | AP35: 0 | AQ35: 0 | AR35: 0 | AS35: 25 | AT35: 326 | AU35: 335 | AV35: 22 | AW35: 501 | AX35: 9 | AY35: 128 | AZ35: 1 | BA35: 0 | BB35: 0 | BC35: 0 | BD35: 1 | BE35: 625 | BF35: 35 | BG35: 0 | BH35: Estadual | BI35: Urbana | BJ35: Não | BK35: Ativa | BL35: Grande | BM35: Rede pública | BN35: Rede pública | BO35: Rede pública | BP35: Serviço de coleta
A36: Sudeste | B36: São Paulo | C36: SP | D36: 35 | E36: Rio Claro | F36: 3543907 | G36: ETEC PROFESSOR ARMANDO BAYEUX DA SILVA | H36: 35021817 | I36: 2 | J36: 1 | K36: 0 | L36: 5 | M36: 445 | N36: AVENIDA | O36: CENTRO | P36: 13500380 | Q36: 1 | R36: 1 | S36: 1 | T36: 0 | U36: 0 | V36: 0 | W36: 0 | X36: 0 | Y36: 1 | Z36: 0 | AA36: 0 | AB36: 0 | AC36: 1 | AD36: 0 | AE36: 0 | AF36: 0 | AG36: 0 | AH36: 1 | AI36: 0 | AJ36: 0 | AK36: 0 | AL36: 0 | AM36: 1169 | AN36: 0 | AO36: 0 | AP36: 606 | AQ36: 977 | AR36: 0 | AS36: 12 | AT36: 569 | AU36: 600 | AV36: 185 | AW36: 772 | AX36: 28 | AY36: 183 | AZ36: 1 | BA36: 0 | BB36: 0 | BC36: 0 | BD36: 0 | BE36: 2 | BF36: 613 | BG36: 554 | BH36: Estadual | BI36: Urbana | BJ36: Não | BK36: Ativa | BL36: Muito Grande | BM36: Rede pública | BN36: Rede pública | BO36: Rede pública | BP36: Serviço de coleta
A37: Sudeste | B37: São Paulo | C37: SP | D37: 35 | E37: Rio Claro | F37: 3543907 | G37: HAMILTON PRADO DEPUTADO FEDERAL | H37: 35036316 | I37: 2 | J37: 1 | L37: R 14 | M37: 3896 | N37: RUA | O37: VL OLINDA | P37: 13504164 | Q37: 2 | BH37: Estadual | BI37: Urbana | BK37: Inativa | BL37: Não informado | BM37: Não informado | BN37: Não informado | BO37: Não informado | BP37: Não informado
A38: Sudeste | B38: São Paulo | C38: SP | D38: 35 | E38: Rio Claro | F38: 3543907 | G38: NELSON STROILI PROFESSOR | H38: 35041661 | I38: 2 | J38: 1 | K38: 0 | L38: M 22 | M38: 951 | N38: RUA | O38: JARDIM IPANEMA | P38: 13505315 | Q38: 1 | R38: 1 | S38: 1 | T38: 0 | U38: 0 | V38: 0 | W38: 0 | X38: 0 | Y38: 1 | Z38: 0 | AA38: 0 | AB38: 0 | AC38: 1 | AD38: 0 | AE38: 0 | AF38: 0 | AG38: 0 | AH38: 1 | AI38: 0 | AJ38: 0 | AK38: 0 | AL38: 0 | AM38: 808 | AN38: 0 | AO38: 342 | AP38: 466 | AQ38: 0 | AR38: 0 | AS38: 22 | AT38: 365 | AU38: 443 | AV38: 21 | AW38: 480 | AX38: 18 | AY38: 285 | AZ38: 3 | BA38: 1 | BB38: 0 | BC38: 0 | BD38: 1 | BE38: 313 | BF38: 449 | BG38: 45 | BH38: Estadual | BI38: Urbana | BJ38: Não | BK38: Ativa | BL38: Grande | BM38: Rede pública | BN38: Rede pública | BO38: Rede pública | BP38: Serviço de coleta
A39: Sudeste | B39: São Paulo | C39: SP | D39: 35 | E39: Rio Claro | F39: 3543907 | G39: JOSE CARDOSO PROFESSOR | H39: 35045895 | I39: 2 | J39: 1 | K39: 0 | L39: 9 | M39: 2383 | N39: RUA | O39: CONJUNTO HABITACIONAL ARCOIRIS CECAP | P39: 13506083 | Q39: 1 | R39: 1 | S39: 1 | T39: 0 | U39: 0 | V39: 0 | W39: 0 | X39: 0 | Y39: 1 | Z39: 0 | AA39: 0 | AB39: 0 | AC39: 1 | AD39: 0 | AE39: 0 | AF39: 0 | AG39: 0 | AH39: 1 | AI39: 0 | AJ39: 0 | AK39: 0 | AL39: 0 | AM39: 1302 | AN39: 0 | AO39: 562 | AP39: 740 | AQ39: 0 | AR39: 0 | AS39: 21 | AT39: 580 | AU39: 722 | AV39: 44 | AW39: 903 | AX39: 23 | AY39: 329 | AZ39: 3 | BA39: 0 | BB39: 0 | BC39: 0 | BD39: 0 | BE39: 517 | BF39: 710 | BG39: 75 | BH39: Estadual | BI39: Urbana | BJ39: Não | BK39: Ativa | BL39: Muito Grande | BM39: Rede pública | BN39: Rede pública | BO39: Rede pública | BP39: Serviço de coleta
A40: Sudeste | B40: São Paulo | C40: SP | D40: 35 | E40: Rio Claro | F40: 3543907 | G40: VICTORINO MACHADO PROF | H40: 35045901 | I40: 2 | J40: 1 | L40: AV 2 | M40: 196 | N40: AVENIDA | O40: BATOVI | P40: 13504763 | Q40: 2 | BH40: Estadual | BI40: Urbana | BK40: Inativa | BL40: Não informado | BM40: Não informado | BN40: Não informado | BO40: Não informado | BP40: Não informado
A41: Sudeste | B41: São Paulo | C41: SP | D41: 35 | E41: Rio Claro | F41: 3543907 | G41: DELCIO BACCARO PROFESSOR | H41: 35049967 | I41: 2 | J41: 1 | K41: 0 | L41: 1 | M41: 303 | N41: COHAB | O41: JARDIM INOCOOP | P41: 13502010 | Q41: 1 | R41: 1 | S41: 1 | T41: 0 | U41: 0 | V41: 0 | W41: 0 | X41: 0 | Y41: 1 | Z41: 0 | AA41: 0 | AB41: 0 | AC41: 1 | AD41: 0 | AE41: 0 | AF41: 0 | AG41: 0 | AH41: 1 | AI41: 0 | AJ41: 0 | AK41: 0 | AL41: 0 | AM41: 999 | AN41: 0 | AO41: 511 | AP41: 488 | AQ41: 77 | AR41: 0 | AS41: 12 | AT41: 465 | AU41: 534 | AV41: 45 | AW41: 552 | AX41: 78 | AY41: 322 | AZ41: 1 | BA41: 1 | BB41: 0 | BC41: 0 | BD41: 2 | BE41: 472 | BF41: 467 | BG41: 58 | BH41: Estadual | BI41: Urbana | BJ41: Não | BK41: Ativa | BL41: Grande | BM41: Rede pública | BN41: Rede pública | BO41: Rede pública | BP41: Serviço de coleta
A42: Sudeste | B42: São Paulo | C42: SP | D42: 35 | E42: Rio Claro | F42: 3543907 | G42: PEDRO DOM I ESCOLA MUNICIPAL | H42: 35061396 | I42: 3 | J42: 1 | K42: 0 | L42: 3 A | M42: 775 | O42: VILA ALEMA | P42: 13506540 | Q42: 1 | R42: 1 | S42: 1 | T42: 0 | U42: 0 | V42: 0 | W42: 0 | X42: 0 | Y42: 1 | Z42: 0 | AA42: 0 | AB42: 0 | AC42: 1 | AD42: 0 | AE42: 0 | AF42: 0 | AG42: 0 | AH42: 1 | AI42: 0 | AJ42: 0 | AK42: 0 | AL42: 0 | AM42: 439 | AN42: 439 | AO42: 0 | AP42: 0 | AQ42: 0 | AR42: 0 | AS42: 16 | AT42: 218 | AU42: 221 | AV42: 11 | AW42: 379 | AX42: 5 | AY42: 44 | AZ42: 0 | BA42: 0 | BB42: 138 | BC42: 267 | BD42: 34 | BE42: 0 | BF42: 0 | BG42: 0 | BH42: Municipal | BI42: Urbana | BJ42: Não | BK42: Ativa | BL42: Média | BM42: Rede pública | BN42: Rede pública | BO42: Rede pública | BP42: Serviço de coleta
A43: Sudeste | B43: São Paulo | C43: SP | D43: 35 | E43: Rio Claro | F43: 3543907 | G43: BENJAMIN FERREIRA ESCOLA MUNICIPAL | H43: 35061402 | I43: 3 | J43: 1 | K43: 0 | L43: 4 B | M43: 70 | N43: RUA | O43: CIDADE NOVA | P43: 13506808 | Q43: 1 | R43: 1 | S43: 1 | T43: 0 | U43: 0 | V43: 0 | W43: 0 | X43: 0 | Y43: 1 | Z43: 0 | AA43: 0 | AB43: 0 | AC43: 1 | AD43: 0 | AE43: 0 | AF43: 0 | AG43: 0 | AH43: 1 | AI43: 0 | AJ43: 0 | AK43: 0 | AL43: 0 | AM43: 102 | AN43: 102 | AO43: 0 | AP43: 0 | AQ43: 0 | AR43: 0 | AS43: 5 | AT43: 51 | AU43: 51 | AV43: 2 | AW43: 84 | AX43: 4 | AY43: 12 | AZ43: 0 | BA43: 0 | BB43: 16 | BC43: 76 | BD43: 10 | BE43: 0 | BF43: 0 | BG43: 0 | BH43: Municipal | BI43: Urbana | BJ43: Não | BK43: Ativa | BL43: Pequena | BM43: Rede pública | BN43: Rede pública | BO43: Rede pública | BP43: Serviço de coleta
A44: Sudeste | B44: São Paulo | C44: SP | D44: 35 | E44: Rio Claro | F44: 3543907 | G44: VICTORINO MACHADO PROF ESCOLA MUNICIPAL | H44: 35061414 | I44: 3 | J44: 1 | K44: 0 | L44: M 27 | M44: 1132 | N44: AVENIDA | O44: PARQUE DAS INDUSTRIAS | P44: 13505006 | Q44: 1 | R44: 1 | S44: 1 | T44: 0 | U44: 0 | V44: 0 | W44: 0 | X44: 0 | Y44: 1 | Z44: 0 | AA44: 0 | AB44: 0 | AC44: 1 | AD44: 0 | AE44: 0 | AF44: 0 | AG44: 0 | AH44: 1 | AI44: 0 | AJ44: 0 | AK44: 0 | AL44: 0 | AM44: 765 | AN44: 404 | AO44: 316 | AP44: 0 | AQ44: 0 | AR44: 45 | AS44: 26 | AT44: 387 | AU44: 378 | AV44: 185 | AW44: 364 | AX44: 34 | AY44: 181 | AZ44: 1 | BA44: 0 | BB44: 75 | BC44: 299 | BD44: 336 | BE44: 10 | BF44: 0 | BG44: 45 | BH44: Municipal | BI44: Urbana | BJ44: Não | BK44: Ativa | BL44: Grande | BM44: Rede pública | BN44: Rede pública | BO44: Rede pública | BP44: Serviço de coleta
...

Sheet Infraestrutura
A1: ="Indicadores de infraestrutura — "&Filtro_Municipio!B3&" ("&Filtro_Municipio!B2&")" -> Indicadores de infraestrutura — Rio Claro (SP)
A3: Água | D3: Energia | G3: Esgoto | J3: Lixo
A4: Categoria | B4: Escolas | D4: Categoria | E4: Escolas | G4: Categoria | H4: Escolas | J4: Categoria | K4: Escolas
A5: Rede pública | B5: =COUNTIF(DadosTratados!$BM:$BM,A5) -> 122 | D5: Rede pública | E5: =COUNTIF(DadosTratados!$BN:$BN,D5) -> 122 | G5: Rede pública | H5: =COUNTIF(DadosTratados!$BO:$BO,G5) -> 120 | J5: Serviço de coleta | K5: =COUNTIF(DadosTratados!$BP:$BP,J5) -> 121
A6: Poço artesiano | B6: =COUNTIF(DadosTratados!$BM:$BM,A6) -> 0 | D6: Gerador fóssil | E6: =COUNTIF(DadosTratados!$BN:$BN,D6) -> 0 | G6: Fossa séptica | H6: =COUNTIF(DadosTratados!$BO:$BO,G6) -> 2 | J6: Queima | K6: =COUNTIF(DadosTratados!$BP:$BP,J6) -> 0
A7: Cacimba | B7: =COUNTIF(DadosTratados!$BM:$BM,A7) -> 0 | D7: Renovável | E7: =COUNTIF(DadosTratados!$BN:$BN,D7) -> 0 | G7: Fossa comum | H7: =COUNTIF(DadosTratados!$BO:$BO,G7) -> 0 | J7: Enterra | K7: =COUNTIF(DadosTratados!$BP:$BP,J7) -> 0
A8: Fonte/Rio | B8: =COUNTIF(DadosTratados!$BM:$BM,A8) -> 0 | D8: Inexistente | E8: =COUNTIF(DadosTratados!$BN:$BN,D8) -> 0 | G8: Fossa rudimentar | H8: =COUNTIF(DadosTratados!$BO:$BO,G8) -> 0 | J8: Destino final público | K8: =COUNTIF(DadosTratados!$BP:$BP,J8) -> 0
A9: Inexistente | B9: =COUNTIF(DadosTratados!$BM:$BM,A9) -> 0 | D9: Não informado | E9: =COUNTIF(DadosTratados!$BN:$BN,D9) -> 21 | G9: Inexistente | H9: =COUNTIF(DadosTratados!$BO:$BO,G9) -> 0 | J9: Descarte em outra área | K9: =COUNTIF(DadosTratados!$BP:$BP,J9) -> 1
A10: Carro-pipa | B10: =COUNTIF(DadosTratados!$BM:$BM,A10) -> 0 | G10: Não informado | H10: =COUNTIF(DadosTratados!$BO:$BO,G10) -> 21 | J10: Não informado | K10: =COUNTIF(DadosTratados!$BP:$BP,J10) -> 21
A11: Não informado | B11: =COUNTIF(DadosTratados!$BM:$BM,A11) -> 21
